Workbook

Sheet HOJA RESUMEN
A1: CHILD SENSORY PROFILE 2 | C1: Padres 3 a 14 años
A3: Nombre evaluado(a) | B3: León Escare Pinilla Abello
A6: Fecha de nacimiento | B6: 43897 | C6: Formato (31-12-2024)
A7: Fecha de la evaluación | B7: 45891 | C7: Formato (31-12-2024)
A8: Edad cronológica | B8: =DATEDIF(B6, TODAY(), "Y") & " años, " & DATEDIF(B6, TODAY(), "YM") & " meses, " & DATEDIF(B6, TODAY(), "MD") & " días" -> 5 años, 5 meses, 21 días
A9: ¿Prematuro? Si/No | B9: NO
A12: Cuadrantes | B12: Buscador | C12: =PUNTAJES!F5 -> Más que la mayoría de los demás
B13: Evitador | C13: =PUNTAJES!G5 -> Justo como la mayoría de los demás
B14: Sensibilidad | C14: =PUNTAJES!H5 -> Justo como la mayoría de los demás
B15: Registro | C15: =PUNTAJES!I5 -> Justo como la mayoría de los demás
A16: Secciones Sensoriales | B16: Audición | C16: =PUNTAJES!J5 -> Justo como la mayoría de los demás
B17: Visual | C17: =PUNTAJES!K5 -> Justo como la mayoría de los demás
B18: Tácto | C18: =PUNTAJES!L5 -> Justo como la mayoría de los demás
B19: Movimiento | C19: =PUNTAJES!M5 -> Justo como la mayoría de los demás
B20: Posición corporal | C20: =PUNTAJES!N5 -> Justo como la mayoría de los demás
B21: Oral | C21: =PUNTAJES!O5 -> Justo como la mayoría de los demás
A22: Secciones Conductuales | B22: Conducta | C22: =PUNTAJES!P5 -> Más que la mayoría de los demás
B23: Socioemocional | C23: =PUNTAJES!Q5 -> Más que la mayoría de los demás
B24: Atencional | C24: =PUNTAJES!R5 -> Justo como la mayoría de los demás
A27: Material complementario para la corrección de puntaje y apoyo al análisis de la pauta Perfil Sensorial
A28: Autoría: TO. MG. Maria Francisca Rauch Gajardo

Sheet PUNTAJES
A1: AREA | B1: ITEM | C1: PUNTAJE
A2: PROCESAMIENTO AUDITIVO | B2: 1 | C2: 1 | U2: Buscador | X2: Audición | AA2: Conducta
B3: 2 | C3: 2 | F3: Buscador | G3: Evitador | H3: Sensibilidad | I3: Registro | J3: Audición | K3: Visual | L3: Tacto | M3: Movimiento | N3: Posición corporal | O3: Oral | P3: Conducta | Q3: Socioemocional | R3: Atencional | U3: Valor | V3: Etiqueta | X3: Valor | Y3: Etiqueta | AA3: Valor | AB3: Etiqueta
B4: 3 | C4: 3 | E4: Puntaje Obtenido | F4: =SUM(C15+C22+C23+C26+C28+C29+C31+C32+C33+C42+C49+C50+C51+C52+C56+C57+C61+C83+C84) -> 48 | G4: =C2+C3+C6+C16+C19+C59+C60+C62+C64+C65+C66+C67+C68+C69+C71+C72+C73+C75+C76+C82 -> 44 | H4: =C4+C5+C7+C8+C10+C14+C17+C20+C21+C45+C46+C47+C48+C53+C70+C74+C78+C79+C85 -> 33 | I4: =C9+C13+C24+C25+C27+C34+C35+C36+C37+C38+C39+C40+C41+C54+C55+C58+C63+C77+C80+C81+C86+C87 -> 38 | J4: =SUM(C2:C9) -> 16 | K4: =SUM(C10:C15) -> 9 | L4: =SUM(C17:C27) -> 18 | M4: =SUM(C28:C35) -> 18 | N4: =SUM(C36:C43) -> 14 | O4: =SUM(C44:C53) -> 20 | P4: =SUM(C54:C62) -> 26 | Q4: =SUM(C63:C76) -> 32 | R4: =SUM(C77:C86) -> 17 | U4: 6 | V4: Mucho menos que los demás | X4: 2 | Y4: Mucho menos que los demás | AA4: 1 | AB4: Mucho menos que los demás
B5: 4 | C5: 5 | E5: Resultado en curva normal | F5: =_xlfn.XLOOKUP(F4,U4:U8,V4:V8,0,1) -> Más que la mayoría de los demás | G5: =_xlfn.XLOOKUP(G4,U12:U16,V12:V16,0,1) -> Justo como la mayoría de los demás | H5: =_xlfn.XLOOKUP(H4,U20:U24,V20:V24,0,1) -> Justo como la mayoría de los demás | I5: =_xlfn.XLOOKUP(I4,U28:U32,V28:V32,0,1) -> Justo como la mayoría de los demás | J5: =_xlfn.XLOOKUP(J4,X4:X8,Y4:Y8,0,1) -> Justo como la mayoría de los demás | K5: =_xlfn.XLOOKUP(K4,X12:X16,Y12:Y16,0,1) -> Justo como la mayoría de los demás | L5: =_xlfn.XLOOKUP(L4,X20:X24,Y20:Y24,0,1) -> Justo como la mayoría de los demás | M5: =_xlfn.XLOOKUP(M4,X28:X32,Y28:Y32,0,1) -> Justo como la mayoría de los demás | N5: =_xlfn.XLOOKUP(N4,X36:X40,Y36:Y40,0,1) -> Justo como la mayoría de los demás | O5: =_xlfn.XLOOKUP(O4,X45:X48,Y45:Y48,0,1) -> Justo como la mayoría de los demás | P5: =_xlfn.XLOOKUP(P4,AA4:AA8,AB4:AB8,0,1) -> Más que la mayoría de los demás | Q5: =_xlfn.XLOOKUP(Q4,AA12:AA16,AB12:AB16,0,1) -> Más que la mayoría de los demás | R5: =_xlfn.XLOOKUP(R4,AA20:AA24,AB20:AB24,0,1) -> Justo como la mayoría de los demás | U5: 19 | V5: Menos que los demás | X5: 9 | Y5: Menos que los demás | AA5: 8 | AB5: Menos que los demás
B6: 5 | C6: 1 | U6: 47 | V6: Justo como la mayoría de los demás | X6: 24 | Y6: Justo como la mayoría de los demás | AA6: 22 | AB6: Justo como la mayoría de los demás
B7: 6 | C7: 2 | U7: 60 | V7: Más que la mayoría de los demás | X7: 31 | Y7: Más que la mayoría de los demás | AA7: 29 | AB7: Más que la mayoría de los demás
B8: 7 | C8: 1 | U8: 95 | V8: Mucho más que la mayoría de los demás | X8: 40 | Y8: Mucho más que la mayoría de los demás | AA8: 45 | AB8: Mucho más que la mayoría de los demás
B9: 8 | C9: 1
A10: VISUAL | B10: 9 | C10: 1 | U10: Evitador | X10: Visual | AA10: Socioemocional
B11: 10 | C11: 3 | U11: Valor | V11: Etiqueta | X11: Valor | Y11: Etiqueta | AA11: Valor | AB11: Etiqueta
B12: 11 | C12: 2 | U12: 7 | V12: Mucho menos que los demás | X12: 4 | Y12: Mucho menos que los demás | AA12: 2 | AB12: Mucho menos que los demás
B13: 12 | C13: 1 | U13: 20 | V13: Menos que los demás | X13: 8 | Y13: Menos que los demás | AA13: 12 | AB13: Menos que los demás
B14: 13 | C14: 1 | U14: 46 | V14: Justo como la mayoría de los demás | X14: 17 | Y14: Justo como la mayoría de los demás | AA14: 31 | AB14: Justo como la mayoría de los demás
B15: 14 | C15: 1 | U15: 59 | V15: Más que la mayoría de los demás | X15: 21 | Y15: Más que la mayoría de los demás | AA15: 41 | AB15: Más que la mayoría de los demás
B16: 15 | C16: 1 | U16: 100 | V16: Mucho más que la mayoría de los demás | X16: 30 | Y16: Mucho más que la mayoría de los demás | AA16: 70 | AB16: Mucho más que la mayoría de los demás
A17: TÁCTIL | B17: 16 | C17: 2
B18: 17 | C18: 1 | U18: Sensibilidad | X18: Tacto | AA18: Atencional
B19: 18 | C19: 1 | U19: Valor | V19: Etiqueta | X19: Valor | Y19: Etiqueta | AA19: Valor | AB19: Etiqueta
B20: 19 | C20: 1 | U20: 6 | V20: Mucho menos que los demás | X20: 0 | Y20: Mucho menos que los demás | AA20: 0 | AB20: Mucho menos que los demás
B21: 20 | C21: 1 | U21: 17 | V21: Menos que los demás | X21: 7 | Y21: Menos que los demás | AA21: 8 | AB21: Menos que los demás
B22: 21 | C22: 1 | U22: 42 | V22: Justo como la mayoría de los demás | X22: 21 | Y22: Justo como la mayoría de los demás | AA22: 24 | AB22: Justo como la mayoría de los demás
B23: 22 | C23: 3 | U23: 53 | V23: Más que la mayoría de los demás | X23: 28 | Y23: Más que la mayoría de los demás | AA23: 31 | AB23: Más que la mayoría de los demás
B24: 23 | C24: 1 | U24: 95 | V24: Mucho más que la mayoría de los demás | X24: 55 | Y24: Mucho más que la mayoría de los demás | AA24: 50 | AB24: Mucho más que la mayoría de los demás
B25: 24 | C25: 5
B26: 25 | C26: 1 | U26: Registro | X26: Movimiento
B27: 26 | C27: 1 | U27: Valor | V27: Etiqueta | X27: Valor | Y27: Etiqueta
A28: MOVIMIENTO | B28: 27 | C28: 1 | U28: 6 | V28: Mucho menos que los demás | X28: 1 | Y28: Mucho menos que los demás
B29: 28 | C29: 2 | U29: 18 | V29: Menos que los demás | X29: 6 | Y29: Menos que los demás
B30: 29 | C30: 1 | U30: 43 | V30: Justo como la mayoría de los demás | X30: 18 | Y30: Justo como la mayoría de los demás
B31: 30 | C31: 5 | U31: 55 | V31: Más que la mayoría de los demás | X31: 24 | Y31: Más que la mayoría de los demás
B32: 31 | C32: 5 | U32: 110 | V32: Mucho más que la mayoría de los demás | X32: 40 | Y32: Mucho más que la mayoría de los demás
B33: 32 | C33: 1
B34: 33 | C34: 2 | X34: Posición del cuerpo
B35: 34 | C35: 1 | X35: Valor | Y35: Etiqueta
A36: POSICION DEL CUERPO | B36: 35 | C36: 1 | X36: 0 | Y36: Mucho menos que los demás
B37: 36 | C37: 2 | X37: 4 | Y37: Menos que los demás
B38: 37 | C38: 5 | X38: 15 | Y38: Justo como la mayoría de los demás
B39: 38 | C39: 1 | X39: 19 | Y39: Más que la mayoría de los demás
B40: 39 | C40: 2 | X40: 40 | Y40: Mucho más que la mayoría de los demás
...

Sheet RESUMEN POR CUADRANTE
A2: BUSCADOR
A3: n° | B3: ÁREA | C3: Descripción | D3: Puntaje Obtenido
A4: 14 | B4: Procesamiento Visual | C4: Observa a las personas mientras se mueven alrededor de la habitación | D4: =PUNTAJES!C15 -> 1
A5: 21 | B5: Procesamiento Táctil | C5: Toca personas y objetos al grado de molestar a otras personas | D5: =PUNTAJES!C22 -> 1
A6: 22 | C6: Muestra necesidad de tocar juguetes, superficies o texturas (por ejemplo, quiere experimental la sensación de todo) | D6: =PUNTAJES!C23 -> 3
A7: 25 | C7: Toca personas y objetos más que otros niños/as de su misma edad | D7: =PUNTAJES!C26 -> 1
A8: 27 | B8: Procesamiento de Movimiento | C8: Procura estar en movimiento hasta el grado que llega a interferir con sus actividades diarias (no quedarse quieto, no quedarse sentado sin moverse) | D8: =PUNTAJES!C28 -> 1
A9: 28 | C9: Se mece sentado(a) en una silla, en el piso o estando de pie | D9: =PUNTAJES!C29 -> 2
A10: 30 | C10: Se emociona cuando realiza tareas que implican movimiento | D10: =PUNTAJES!C31 -> 5
A11: 31 | C11: Toma riesgos al trepar/escalar o hacer movimiento que no son seguros | D11: =PUNTAJES!C32 -> 5
A12: 32 | C12: Busca oportunidades de caerse, sin considerar su propia seguridad (por ejemplo, se cae a propósito) | D12: =PUNTAJES!C33 -> 1
A13: 41 | B13: Procesamiento de Posición del cuerpo | C13: Se estira echándose sobre muebles o encima de la gente | D13: =PUNTAJES!C42 -> 1
A14: 48 | B14: Procesamiento Sensorial Oral | C14: Huele objetos que no son comida | D14: =PUNTAJES!C49 -> 1
A15: 49 | C15: Muestra una fuerte preferencia hacia ciertos sabores | D15: =PUNTAJES!C50 -> 2
A16: 50 | C16: Se le antojan ciertos alimentos, sabores u olores | D16: =PUNTAJES!C51 -> 4
A17: 51 | C17: Se mete objetos a la boca (Por ejemplo, lápiz, las manos) | D17: =PUNTAJES!C52 -> 5
A18: 55 | B18: Conducta asociada con el procesamiento sensorial | C18: Toma riesgos excesivos comprometiendo su propia seguridad (por ejemplo, se trepa de un árbol alto, brinca en muebles altos) | D18: =PUNTAJES!C56 -> 5
A19: 56 | C19: Parece ser más activo(a) que otros niños/as de su misma edad. | D19: =PUNTAJES!C57 -> 5
A20: 60 | C20: Parece disfrutar las caídas | D20: =PUNTAJES!C61 -> 2
A21: 82 | B21: Respuestas de Atención asociadas con el procesamiento sensorial | C21: Observa a todas las personas que se mueven alrededor de la habitación | D21: =PUNTAJES!C83 -> 2
A22: 83 | C22: Brinca de una cosa a otra, a tal grado que interfiere con las actividades | D22: =PUNTAJES!C84 -> 1
A24: EVITADOR
A25: n° | B25: ÁREA | C25: Descripción | D25: Puntaje Obtenido
A26: 1 | B26: Procesamiento auditivo | C26: Reacciona fuertemente a sonidos inesperados o altos (por ejemplo, sirenas, perros ladrando, secadora de pelo) | D26: =PUNTAJES!C2 -> 1
A27: 2 | C27: Se cubre los oídos con las manos para protegerlos de sonidos | D27: =PUNTAJES!C3 -> 2
A28: 5 | C28: Se vuelve improductivo(a) con el ruido de fondo (por ejemplo, ventilador, refrigerador) | D28: =PUNTAJES!C6 -> 1
A29: 15 | B29: Procesamiento visual | C29: Le molestan las luces brillantes (por ejemplo, se esconde de la luz del sol que entra por la ventana del automóvil) | D29: =PUNTAJES!C16 -> 1
A30: 18 | B30: Procesamiento Táctil | C30: Muestra una reacción emocional o agresiva cuando alguien lo(a) toca | D30: =PUNTAJES!C19 -> 1
A31: 58 | B31: Conducta asociada con el procesamiento sensorial | C31: Puede ser terco(a)/Necio(a) y poco cooperativo(a) | D31: =PUNTAJES!C59 -> 3
A32: 59 | C32: Hace berrinches | D32: =PUNTAJES!C60 -> 4
A33: 61 | C33: Se resiste al contacto visual mío o de los demás | D33: =PUNTAJES!C62 -> 1
A34: 63 | B34: Respuestas emocionales/sociales asociadas al procesamiento sensorial | C34: Requiere de apoyo positivo para responder a situaciones desafiantes | D34: =PUNTAJES!C64 -> 1
A35: 64 | C35: Es sensible a las críticas | D35: =PUNTAJES!C65 -> 5
A36: 65 | C36: Tiene miedos predecibles y definidos | D36: =PUNTAJES!C66 -> 5
A37: 66 | C37: Manifiesta sentirse como un fracaso | D37: =PUNTAJES!C67 -> 2
A38: 67 | C38: Es muy serio(a) | D38: =PUNTAJES!C68 -> 2
A39: 68 | C39: Tiene fuertes arrebatos emocionales cuando no puede completar una tarea | D39: =PUNTAJES!C69 -> 5
A40: 70 | C40: Se frustra fácilmente | D40: =PUNTAJES!C71 -> 5
A41: 71 | C41: Tiene temores que interfieren con la rutina cotidiana | D41: =PUNTAJES!C72 -> 1
A42: 72 | C42: Se angustia cuando hay cambios en los planes, rutinas o expectativas | D42: =PUNTAJES!C73 -> 1
...
